<?xml version="1.0"?>
<robot xmlns:xacro="https://www.ros.org/wiki/xacro">
<xacro:include filename="inertial_macros.xacro"/>

<!-- COLOR PARAMETERS-->

<material name="white">
    <color rgba="1 1 1 1"/>
</material>

<material name="orange">
    <color rgba="1 0.3 0.1 1"/>
</material>

<material name="blue">
    <color rgba="0.2 0.2 1 1"/>
</material>

<material name="black">
    <color rgba="0 0 0 1"/>
</material>

<!--PROPERTIES-->
<xacro:property name="caster_wheel_radius" value="0.05"/>
<xacro:property name="caster_wheel_origin_xyz" value="0.24 0 0"/>
<xacro:property name="caster_wheel_origin_rpy" value="0 0 0"/>

<xacro:property name="left_wheel_radius" value="0.05"/>
<xacro:property name="left_wheel_length" value="0.05"/>
<xacro:property name="left_wheel_origin_xyz" value="0 0.175 0"/>
<xacro:property name="left_wheel_origin_rpy" value="-${pi/2} 0 0"/>

<xacro:property name="right_wheel_radius" value="0.05"/>
<xacro:property name="right_wheel_length" value="0.05"/>
<xacro:property name="right_wheel_origin_xyz" value="0 -0.175 0"/>
<xacro:property name="right_wheel_origin_rpy" value="${pi/2} 0 0"/>

<xacro:property name="chassis_origin_xyz" value="0.15 0 0.075"/>
<xacro:property name="chassis_origin_rpy" value="0 0 0"/>
<xacro:property name="chassis_joint_origin_xyz" value="-0.1 0 0"/>
<xacro:property name="chassis_dimensions" value="0.3 0.3 0.15"/>







<link name="base_link">
</link>

<!-- CHASSIS-->
<joint name="chassis_joint" type="fixed">
    <parent link="base_link"/>
    <child link="chassis"/> 
    <origin xyz="${chassis_joint_origin_xyz}"/>
</joint>

<link name="chassis">
    <visual> 
        <origin xyz="0.15 0 0.075" rpy="0 0 0"/>
        <geometry>
            <box size="${chassis_dimensions}"/>
        </geometry>

        <material name="orange"/>
    </visual>

    <collision>
        <origin xyz="${chassis_origin_xyz}" rpy="${chassis_origin_rpy}"/> 
        <geometry>
            <box size="${chassis_dimensions}"/>
        </geometry>
    </collision>

    <xacro:inertial_box mass="0.5" x="0.3" y="0.3" z="0.15">
        <origin xyz="${chassis_origin_xyz}" rpy="${chassis_origin_rpy}"/>
    </xacro:inertial_box>
</link>

<gazebo reference="chassis">
    <material>Gazebo/Orange</material>
</gazebo>

<!-- LEFT WHEEL-->

<joint name="left_wheel_joint" type="continuous">
    <parent link="base_link"/>
    <child link="left_wheel"/>
    <origin xyz="${left_wheel_origin_xyz}" rpy="${left_wheel_origin_rpy}"/>
    <axis xyz="0 0 1"/>
</joint>

<link name="left_wheel">
    <visual>
        <geometry> 
            <cylinder length="${left_wheel_length}" radius="${left_wheel_radius}" />
        </geometry>
        <material name="blue"/>
    </visual>
    <collision>
        <geometry>
            <cylinder length="${left_wheel_length}" radius="${left_wheel_radius}" />
        </geometry>
    </collision>
    <xacro:inertial_cylinder mass="0.1" length="0.05" radius="0.05">
        <origin xyz="0 0 0" rpy="0 0 0"/>
    </xacro:inertial_cylinder>
</link>

<gazebo reference="left_wheel">
    <material>Gazebo/Blue</material>
</gazebo>

<!-- RIGHT WHEEL-->
<joint name="right_wheel_joint" type="continuous">
    <parent link="base_link"/>
    <child link="right_wheel"/>
    
    <origin xyz="${right_wheel_origin_xyz}" rpy="${right_wheel_origin_rpy}"/>
    <axis xyz="0 0 -1"/>
</joint>

<link name="right_wheel">
    <visual>
        <geometry>
            <cylinder length="${right_wheel_length}" radius="${right_wheel_radius}" />
        </geometry>
        <material name="blue"/>
    </visual>
    <collision>
        <geometry>
            <cylinder length="${right_wheel_length}" radius="${right_wheel_radius}" />
        </geometry>
    </collision>
    <xacro:inertial_cylinder mass="0.1" length="0.05" radius="0.05">
        <origin xyz="0 0 0" rpy="0 0 0"/>
    </xacro:inertial_cylinder>
</link>

<gazebo reference="right_wheel">
    <material>Gazebo/Blue</material>
</gazebo>
<!-- CASTER WHEEL -->

<xacro:property name="caster_wheel_radius" value="0.05"/>
<joint name="caster_wheel_joint" type="fixed">
    <parent link="chassis"/>
    <child link="caster_wheel"/>
    <origin xyz="${caster_wheel_origin_xyz}" rpy="${caster_wheel_origin_rpy}"/>
</joint>

<link name="caster_wheel">
    <visual>
        <geometry> 
            <sphere radius="${caster_wheel_radius}"/>
        </geometry>
        
        <material name="black"/>
    </visual>
    <collision>   
        <geometry>
            <sphere radius="0.05"/>
        </geometry>
    </collision>
    <xacro:inertial_sphere mass="0.1" radius="0.05">
        <origin xyz="0 0 0" rpy="0 0 0"/>
    </xacro:inertial_sphere>
</link>

<gazebo reference="caster_wheel">
    <material>Gazebo/Black</material>
</gazebo>

</robot>